<?xml version="1.0" encoding="utf-8"?>
<robot xmlns:xacro="http://www.ros.org/wiki/xacro" name="Elevex">

<!-- BASE_FOOTPRINT LINK -->

  <joint name="base_footprint_joint" type="fixed">
      <parent link="base_link"/>
      <child link="base_footprint"/>
      <origin xyz="0.0488207268870813 0 -0.28" rpy="0 0 0"/>
  </joint>

  <link name="base_footprint">
  </link>

  <link name="base_link">
    <inertial>
      <origin
        xyz="0.0080711 0.0008587 0.16048"
        rpy="0 0 0" />
      <mass value="30.168" />
      <inertia
        ixx="0.60427"
        ixy="-0.12444"
        ixz="0.010189"
        iyy="1.0841"
        iyz="0.0042376"
        izz="1.4144" />
    </inertial>
    <visual>
      <origin
        xyz="0 0 0"
        rpy="0 0 0" />
      <geometry>
        <mesh
          filename="file://$(find robot)/meshes/base_link.STL" />
      </geometry>
      <material
        name="">
        <color
          rgba="0.50196 0.50196 0.50196 1" />
      </material>
    </visual>
    <collision>
      <origin
        xyz="0 0 0"
        rpy="0 0 0" />
      <geometry>
        <mesh
          filename="file://$(find robot)/meshes/base_link.STL" />
      </geometry>
    </collision>
  </link>
  <link
    name="LEFT_wheel_drive">
    <inertial>
      <origin
        xyz="0 0 -0.03"
        rpy="0 0 0" />
      <mass
        value="0.79338" />
      <inertia
        ixx="0.0010792"
        ixy="7.3437E-21"
        ixz="-1.0625E-19"
        iyy="0.0010792"
        iyz="-7.2396E-20"
        izz="0.0016824" />
    </inertial>
    <visual>
      <origin
        xyz="0 0 0"
        rpy="0 0 0" />
      <geometry>
        <mesh
          filename="file://$(find robot)/meshes/LEFT_wheel_drive.STL" />
      </geometry>
      <material
        name="">
        <color
          rgba="0.25098 0.25098 0.25098 1" />
      </material>
    </visual>
    <collision>
      <origin
        xyz="0 0 0"
        rpy="0 0 0" />
      <geometry>
        <mesh
          filename="file://$(find robot)/meshes/LEFT_wheel_drive.STL" />
      </geometry>
    </collision>
  </link>
  <joint
    name="left_wheel_joint"
    type="continuous">
    <origin
      xyz="-0.048718 -0.29 -0.215"
      rpy="1.5708 0 0" />
    <parent
      link="base_link" />
    <child
      link="LEFT_wheel_drive" />
    <axis
      xyz="0 0 -1" />
    <limit
      lower="0"
      upper="0"
      effort="0"
      velocity="0" />
  </joint>
  <link
    name="Right_wheel_drive">
    <inertial>
      <origin
        xyz="2.77555756156289E-17 0 0.03"
        rpy="0 0 0" />
      <mass
        value="0.793377808737566" />
      <inertia
        ixx="0.00107919216433527"
        ixy="7.35016536443278E-21"
        ixz="2.31128990003681E-19"
        iyy="0.00107919216433527"
        iyz="6.91140355312497E-20"
        izz="0.00168235764342801" />
    </inertial>
    <visual>
      <origin
        xyz="0 0 0"
        rpy="0 0 0" />
      <geometry>
        <mesh
          filename="file://$(find robot)/meshes/Right_wheel_drive.STL" />
      </geometry>
      <material
        name="">
        <color
          rgba="0.250980392156863 0.250980392156863 0.250980392156863 1" />
      </material>
    </visual>
    <collision>
      <origin
        xyz="0 0 0"
        rpy="0 0 0" />
      <geometry>
        <mesh
          filename="file://$(find robot)/meshes/Right_wheel_drive.STL" />
      </geometry>
    </collision>
  </link>
  <joint
    name="Right_wheel_joint"
    type="continuous">
    <origin
      xyz="-0.0487177978870813 0.29 -0.215"
      rpy="1.5707963267949 0 0" />
    <parent
      link="base_link" />
    <child
      link="Right_wheel_drive" />
    <axis
      xyz="0 0 -1" />
    <limit
      lower="0"
      upper="0"
      effort="0"
      velocity="0" />
  </joint>
  <link
    name="LF_caster">
    <inertial>
      <origin
        xyz="0 0 -0.01"
        rpy="0 0 0" />
      <mass
        value="0.099526" />
      <inertia
        ixx="4.3526E-05"
        ixy="-1.2962E-21"
        ixz="1.7775E-21"
        iyy="4.3526E-05"
        iyz="1.823E-22"
        izz="8.0417E-05" />
    </inertial>
    <visual>
      <origin
        xyz="0 0 0"
        rpy="0 0 0" />
      <geometry>
        <mesh
          filename="file://$(find robot)/meshes/LF_caster.STL" />
      </geometry>
      <material
        name="">
        <color
          rgba="0.50196 0.50196 0.50196 1" />
      </material>
    </visual>
    <collision>
      <origin
        xyz="0 0 0"
        rpy="0 0 0" />
      <geometry>
        <mesh
          filename="file://$(find robot)/meshes/LF_caster.STL" />
      </geometry>
    </collision>
  </link>
  <joint
    name="LF_caster_jont"
    type="fixed">
    <origin
      xyz="-0.252419974626545 -0.195 -0.24"
      rpy="1.5707963267949 0 0" />
    <parent
      link="base_link" />
    <child
      link="LF_caster" />
    <axis
      xyz="0 0 -1" />
    <limit
      lower="0"
      upper="0"
      effort="0"
      velocity="0" />
  </joint>
  <link
    name="RF_caster">
    <inertial>
      <origin
        xyz="0 0 0.01"
        rpy="0 0 0" />
      <mass
        value="0.0995256552657247" />
      <inertia
        ixx="4.35258865695436E-05"
        ixy="-1.29629003215672E-21"
        ixz="6.11428979929594E-21"
        iyy="4.35258865695436E-05"
        iyz="1.62909581375164E-22"
        izz="8.04167294547055E-05" />
    </inertial>
    <visual>
      <origin
        xyz="0 0 0"
        rpy="0 0 0" />
      <geometry>
        <mesh
          filename="file://$(find robot)/meshes/RF_caster.STL" />
      </geometry>
      <material
        name="">
        <color
          rgba="0.501960784313725 0.501960784313725 0.501960784313725 1" />
      </material>
    </visual>
    <collision>
      <origin
        xyz="0 0 0"
        rpy="0 0 0" />
      <geometry>
        <mesh
          filename="file://$(find robot)/meshes/RF_caster.STL" />
      </geometry>
    </collision>
  </link>
  <joint
    name="RF_caster_joint"
    type="fixed">
    <origin
      xyz="-0.25242 0.195 -0.24"
      rpy="1.5708 0 0" />
    <parent
      link="base_link" />
    <child
      link="RF_caster" />
    <axis
      xyz="0 0 -1" />
    <limit
      lower="0"
      upper="0"
      effort="0"
      velocity="0" />
  </joint>
  <link
    name="LR_Caster">
    <inertial>
      <origin
        xyz="0 0 -0.00999999999999995"
        rpy="0 0 0" />
      <mass
        value="0.0995256552657247" />
      <inertia
        ixx="4.35258865695436E-05"
        ixy="1.29620925280002E-21"
        ixz="6.12311305916317E-21"
        iyy="4.35258865695436E-05"
        iyz="-1.62909581375164E-22"
        izz="8.04167294547056E-05" />
    </inertial>
    <visual>
      <origin
        xyz="0 0 0"
        rpy="0 0 0" />
      <geometry>
        <mesh
          filename="file://$(find robot)/meshes/LR_Caster.STL" />
      </geometry>
      <material
        name="">
        <color
          rgba="0.501960784313725 0.501960784313725 0.501960784313725 1" />
      </material>
    </visual>
    <collision>
      <origin
        xyz="0 0 0"
        rpy="0 0 0" />
      <geometry>
        <mesh
          filename="file://$(find robot)/meshes/LR_Caster.STL" />
      </geometry>
    </collision>
  </link>
  <joint
    name="LR_Caster_joint"
    type="fixed">
    <origin
      xyz="0.25242 -0.195 -0.24"
      rpy="1.5708 0 0" />
    <parent
      link="base_link" />
    <child
      link="LR_Caster" />
    <axis
      xyz="0 0 1" />
    <limit
      lower="0"
      upper="0"
      effort="0"
      velocity="0" />
  </joint>
  <link
    name="RR_caster">
    <inertial>
      <origin
        xyz="2.77555756156289E-17 0 0.01"
        rpy="0 0 0" />
      <mass
        value="0.0995256552657247" />
      <inertia
        ixx="4.35258865695436E-05"
        ixy="1.29629003215672E-21"
        ixz="1.78627658484092E-21"
        iyy="4.35258865695436E-05"
        iyz="-4.1128303054583E-23"
        izz="8.04167294547056E-05" />
    </inertial>
    <visual>
      <origin
        xyz="0 0 0"
        rpy="0 0 0" />
      <geometry>
        <mesh
          filename="file://$(find robot)/meshes/RR_caster.STL" />
      </geometry>
      <material
        name="">
        <color
          rgba="0.501960784313725 0.501960784313725 0.501960784313725 1" />
      </material>
    </visual>
    <collision>
      <origin
        xyz="0 0 0"
        rpy="0 0 0" />
      <geometry>
        <mesh
          filename="file://$(find robot)/meshes/RR_caster.STL" />
      </geometry>
    </collision>
  </link>
  <joint
    name="RR_caster_joint"
    type="fixed">
    <origin
      xyz="0.25242 0.195 -0.24"
      rpy="1.5708 0 0" />
    <parent
      link="base_link" />
    <child
      link="RR_caster" />
    <axis
      xyz="0 0 1" />
    <limit
      lower="0"
      upper="0"
      effort="0"
      velocity="0" />
  </joint>
  <link
    name="Left_motor">
    <inertial>
      <origin
        xyz="-1.3878E-17 0.0039017 0.032653"
        rpy="0 0 0" />
      <mass
        value="1.9465" />
      <inertia
        ixx="0.0020859"
        ixy="8.2949E-20"
        ixz="-6.1628E-20"
        iyy="0.0019442"
        iyz="6.1524E-05"
        izz="0.0010535" />
    </inertial>
    <visual>
      <origin
        xyz="0 0 0"
        rpy="0 0 0" />
      <geometry>
        <mesh
          filename="file://$(find robot)/meshes/Left_motor.STL" />
      </geometry>
      <material
        name="">
        <color
          rgba="0.52941 0.54902 0.54902 1" />
      </material>
    </visual>
    <collision>
      <origin
        xyz="0 0 0"
        rpy="0 0 0" />
      <geometry>
        <mesh
          filename="file://$(find robot)/meshes/Left_motor.STL" />
      </geometry>
    </collision>
  </link>
  <joint
    name="Left_motor_joint"
    type="fixed">
    <origin
      xyz="-0.048718 -0.12931 -0.225"
      rpy="1.5708 0 0" />
    <parent
      link="base_link" />
    <child
      link="Left_motor" />
    <axis
      xyz="0 0 0" />
  </joint>
  <link
    name="Right_motor">
    <inertial>
      <origin
        xyz="-2.77555756156289E-17 0.00390171963174921 -0.0326533283816412"
        rpy="0 0 0" />
      <mass
        value="1.94648139909599" />
      <inertia
        ixx="0.0020859276474203"
        ixy="-2.65946441215283E-19"
        ixz="-5.57311168075214E-19"
        iyy="0.00194416330236325"
        iyz="-6.15235281943915E-05"
        izz="0.00105347397549006" />
    </inertial>
    <visual>
      <origin
        xyz="0 0 0"
        rpy="0 0 0" />
      <geometry>
        <mesh
          filename="file://$(find robot)/meshes/Right_motor.STL" />
      </geometry>
      <material
        name="">
        <color
          rgba="0.529411764705882 0.549019607843137 0.549019607843137 1" />
      </material>
    </visual>
    <collision>
      <origin
        xyz="0 0 0"
        rpy="0 0 0" />
      <geometry>
        <mesh
          filename="file://$(find robot)/meshes/Right_motor.STL" />
      </geometry>
    </collision>
  </link>
  <joint
    name="Right_motor_joint"
    type="fixed">
    <origin
      xyz="-0.048718 0.12931 -0.225"
      rpy="1.5708 0 0" />
    <parent
      link="base_link" />
    <child
      link="Right_motor" />
    <axis
      xyz="0 0 0" />
  </joint>
  <link
    name="laser_frame">
    <inertial>
      <origin
        xyz="0 0 0"
        rpy="0 0 0" />
      <mass
        value="0" />
      <inertia
        ixx="0"
        ixy="0"
        ixz="0"
        iyy="0"
        iyz="0"
        izz="0" />
    </inertial>
    <visual>
      <origin
        xyz="0 0 0"
        rpy="0 0 0" />
      <geometry>
        <mesh
          filename="file://$(find robot)/meshes/Lidar.STL" />
      </geometry>
      <material
        name="">
        <color
          rgba="1 1 1 1" />
      </material>
    </visual>
    <collision>
      <origin
        xyz="0 0 0"
        rpy="0 0 0" />
      <geometry>
        <mesh
          filename="file://$(find robot)/meshes/Lidar.STL" />
      </geometry>
    </collision>
  </link>
  <joint
    name="laser_joint"
    type="fixed">
    <origin
      xyz="0.31569 -0.0093261 0.22363"
      rpy="0 0 0" />
    <parent
      link="base_link" />
    <child
      link="laser_frame" />
    <axis
      xyz="0 0 0" />
  </joint>

  <xacro:include filename="ros2_control.xacro" />
</robot>